Workbook

Sheet Plate
A1: Addition #1 | B1: Name | C1: Final added | D1: Stock | E1: unit | G1: Addition #2 | H1: Name | I1: Final added | J1: Stock | K1: unit
A2: A1 | B2: Glucose | C2: 13 | D2: 500 | E2: mM | G2: =A2 -> A1 | H2: Oligom | I2: 2 | J2: =4000*I2 -> 8000 | K2: ug/ml
A3: B1 | B3: Glucose+FCCP | C3: 100 | D3: 120000 | E3: nM | G3: =A3 -> B1 | H3: Oligom | I3: 2 | J3: =4000*I3 -> 8000 | K3: ug/ml
A4: C1
A5: D1
A6: E1
A7: F1
A8: A2
A9: B2
A10: C2
A11: D2
A12: E2
A13: F2
A14: A3
A15: B3
... A25: F4
A26: def | B26: Glucose | C26: 13 | D26: 500 | E26: mM | G26: =A26 -> def
A27: veh | B27: DMSO | C27: 1 | D27: 4000 | E27: x | G27: =A27 -> veh
A30: DO NOT USE CUT (Ctrl-X) TO EDIT THE ABOVE LIST! | D30: Possible units above: nM, uM, mM, ug/ml, mg/ml, x | G30: Final and stock concentrations are in the same units
A31: Starting assay volume (ul) | C31: 100
A32: Addition paradigm: | C32: minus (ul) | D32: 50 | E32: then plus (ul) | F32: 50 | H32: dilution= | I32: =(C31-D32+F32)/F32 -> 2 | J32: =I32 -> 2 | K32: =J32 -> 2
A33: Max reservoir volumes for additions #1, 2, 3 (ul)= | C33: 200 | E33: 150 | G33: 0 | H33: ul
A34: Final reservoir volumes for additions #1, 2, 3 (ul)= | C34: =C33-E33/2-G33/4 -> 125 | E34: =E35+E87 -> 150 | G34: =G33 -> 0 | J34: Automatic Tally (DO NOT EDIT) | M34: Needed: | P34: Prepare
A35: DO NOT EDIT! | B35: Addition #1 make it in volume= | C35: =C33 -> 200 | D35: Addition #2 make it in volume= | E35: =$E$33-SUM($E$87:$E$88) -> 75 | F35: Addition #3 make it in volume= | G35: =$G$33-SUM($G$87:$G$88) -> 0 | J35: Name (use =and pick cell from column B) | M35: reagent (ul) | N35: medium (ul) | P35: ul drug | Q35: ul medium
A36: =A2 -> A1 | B36: =B2&" "&SUBSTITUTE(SUBSTITUTE(SUBSTITUTE(D2&E2,"000nM","uM"),"000uM","mM"),"000ug","mg")&" "&ROUND(1/(C37/C36+1),5)&"x" -> Glucose 500mM 0.052x | C36: =$I$32*C2/D2*$C$33 -> 10.4 | D36: =H2&" "&SUBSTITUTE(SUBSTITUTE(SUBSTITUTE(J2&K2,"000nM","uM"),"000uM","mM"),"000ug","mg")&" "&ROUND(1/(E37/E36+1),5)&"x" -> Oligom 8mg/ml 0.001x | E36: =$I$32*I2/J2*$E$33 -> 0.075 | F36: =N2&" "&SUBSTITUTE(SUBSTITUTE(SUBSTITUTE(P2&Q2,"000nM","uM"),"000uM","mM"),"000ug","mg")&" "&ROUND(1/(G37/G36+1),5)&"x" -> #DIV/0! | G36: =$K$32*O2/P2*$G$33 -> #DIV/0! | H36: Version 1.3 | J36: =Tally!C2 -> Glucose 500mM 0.052x | M36: =SUMIF($B$36:$F$86,J36,$C$36:$G$85) -> 10.4 | N36: =SUMIF($B$36:$F$85,J36,$C$37:$G$85) -> 189.6 | P36: =M36/N36*Q36 -> 27.42616 | Q36: =ROUND(MAX(1.1*N36,0.5*N36/M36)/500+0.5,0)*500 -> 500
B37: medium | C37: =$C$33-C36 -> 189.6 | D37: medium | E37: =$E$33-SUM($E$87:$E$88)-E36 -> 74.925 | F37: medium | G37: =$G$33-SUM($G$87:$G$88)-G36 -> #DIV/0! | H37: 46234 | J37: =Tally!C3 -> Glucose+FCCP 120uM 0.00167x | M37: =SUMIF($B$36:$F$86,J37,$C$36:$G$85) -> 0.33333333 | N37: =SUMIF($B$36:$F$85,J37,$C$37:$G$85) -> 199.66667 | P37: =M37/N37*Q37 -> 0.83472454 | Q37: =ROUND(MAX(1.1*N37,0.5*N37/M37)/500+0.5,0)*500 -> 500
A38: =A3 -> B1 | B38: =B3&" "&SUBSTITUTE(SUBSTITUTE(SUBSTITUTE(D3&E3,"000nM","uM"),"000uM","mM"),"000ug","mg")&" "&ROUND(1/(C39/C38+1),5)&"x" -> Glucose+FCCP 120uM 0.00167x | C38: =$I$32*C3/D3*$C$33 -> 0.33333333 | D38: =H3&" "&SUBSTITUTE(SUBSTITUTE(SUBSTITUTE(J3&K3,"000nM","uM"),"000uM","mM"),"000ug","mg")&" "&ROUND(1/(E39/E38+1),5)&"x" -> Oligom 8mg/ml 0.001x | E38: =$I$32*I3/J3*$E$33 -> 0.075 | F38: =N3&" "&SUBSTITUTE(SUBSTITUTE(SUBSTITUTE(P3&Q3,"000nM","uM"),"000uM","mM"),"000ug","mg")&" "&ROUND(1/(G39/G38+1),5)&"x" -> #DIV/0! | G38: =$K$32*O3/P3*$G$33 -> #DIV/0! | J38: =Tally!C4 -> Oligom 8mg/ml 0.001x | M38: =SUMIF($B$36:$F$86,J38,$C$36:$G$85) -> 0.15 | N38: =SUMIF($B$36:$F$85,J38,$C$37:$G$85) -> 149.85 | P38: =M38/N38*Q38 -> 0.5005005 | Q38: =ROUND(MAX(1.1*N38,0.5*N38/M38)/500+0.5,0)*500 -> 500
B39: medium | C39: =$C$33-C38 -> 199.66667 | D39: medium | E39: =$E$33-SUM($E$87:$E$88)-E38 -> 74.925 | F39: medium | G39: =$G$33-SUM($G$87:$G$88)-G38 -> #DIV/0! | J39: =Tally!C5 | M39: =SUMIF($B$36:$F$86,J39,$C$36:$G$85) -> 0 | N39: =SUMIF($B$36:$F$85,J39,$C$37:$G$85) -> #DIV/0! | P39: =M39/N39*Q39 -> #DIV/0! | Q39: =ROUND(MAX(1.1*N39,0.5*N39/M39)/500+0.5,0)*500 -> #DIV/0!
A40: =A4 -> C1 | B40: =B4&" "&SUBSTITUTE(SUBSTITUTE(SUBSTITUTE(D4&E4,"000nM","uM"),"000uM","mM"),"000ug","mg")&" "&ROUND(1/(C41/C40+1),5)&"x" -> #DIV/0! | C40: =$I$32*C4/D4*$C$33 -> #DIV/0! | D40: =H4&" "&SUBSTITUTE(SUBSTITUTE(SUBSTITUTE(J4&K4,"000nM","uM"),"000uM","mM"),"000ug","mg")&" "&ROUND(1/(E41/E40+1),5)&"x" -> #DIV/0! | E40: =$I$32*I4/J4*$E$33 -> #DIV/0! | F40: =N4&" "&SUBSTITUTE(SUBSTITUTE(SUBSTITUTE(P4&Q4,"000nM","uM"),"000uM","mM"),"000ug","mg")&" "&ROUND(1/(G41/G40+1),5)&"x" -> #DIV/0! | G40: =$K$32*O4/P4*$G$33 -> #DIV/0! | J40: =Tally!C6 | M40: =SUMIF($B$36:$F$86,J40,$C$36:$G$85) -> 0 | N40: =SUMIF($B$36:$F$85,J40,$C$37:$G$85) -> #DIV/0! | P40: =M40/N40*Q40 -> #DIV/0! | Q40: =ROUND(MAX(1.1*N40,0.5*N40/M40)/500+0.5,0)*500 -> #DIV/0!
B41: medium | C41: =$C$33-C40 -> #DIV/0! | D41: medium | E41: =$E$33-SUM($E$87:$E$88)-E40 -> #DIV/0! | F41: medium | G41: =$G$33-SUM($G$87:$G$88)-G40 -> #DIV/0! | J41: =Tally!C7 | M41: =SUMIF($B$36:$F$86,J41,$C$36:$G$85) -> 0 | N41: =SUMIF($B$36:$F$85,J41,$C$37:$G$85) -> #DIV/0! | P41: =M41/N41*Q41 -> #DIV/0! | Q41: =ROUND(MAX(1.1*N41,0.5*N41/M41)/500+0.5,0)*500 -> #DIV/0!
A42: =A5 -> D1 | B42: =B5&" "&SUBSTITUTE(SUBSTITUTE(SUBSTITUTE(D5&E5,"000nM","uM"),"000uM","mM"),"000ug","mg")&" "&ROUND(1/(C43/C42+1),5)&"x" -> #DIV/0! | C42: =$I$32*C5/D5*$C$33 -> #DIV/0! | D42: =H5&" "&SUBSTITUTE(SUBSTITUTE(SUBSTITUTE(J5&K5,"000nM","uM"),"000uM","mM"),"000ug","mg")&" "&ROUND(1/(E43/E42+1),5)&"x" -> #DIV/0! | E42: =$I$32*I5/J5*$E$33 -> #DIV/0! | F42: =N5&" "&SUBSTITUTE(SUBSTITUTE(SUBSTITUTE(P5&Q5,"000nM","uM"),"000uM","mM"),"000ug","mg")&" "&ROUND(1/(G43/G42+1),5)&"x" -> #DIV/0! | G42: =$K$32*O5/P5*$G$33 -> #DIV/0! | J42: =Tally!C8 | M42: =SUMIF($B$36:$F$86,J42,$C$36:$G$85) -> 0 | N42: =SUMIF($B$36:$F$85,J42,$C$37:$G$85) -> #DIV/0! | P42: =M42/N42*Q42 -> #DIV/0! | Q42: =ROUND(MAX(1.1*N42,0.5*N42/M42)/500+0.5,0)*500 -> #DIV/0!
B43: medium | C43: =$C$33-C42 -> #DIV/0! | D43: medium | E43: =$E$33-SUM($E$87:$E$88)-E42 -> #DIV/0! | F43: medium | G43: =$G$33-SUM($G$87:$G$88)-G42 -> #DIV/0! | J43: =Tally!C9 | M43: =SUMIF($B$36:$F$86,J43,$C$36:$G$85) -> 0 | N43: =SUMIF($B$36:$F$85,J43,$C$37:$G$85) -> #DIV/0! | P43: =M43/N43*Q43 -> #DIV/0! | Q43: =ROUND(MAX(1.1*N43,0.5*N43/M43)/500+0.5,0)*500 -> #DIV/0!
A44: =A6 -> E1 | B44: =B6&" "&SUBSTITUTE(SUBSTITUTE(SUBSTITUTE(D6&E6,"000nM","uM"),"000uM","mM"),"000ug","mg")&" "&ROUND(1/(C45/C44+1),5)&"x" -> #DIV/0! | C44: =$I$32*C6/D6*$C$33 -> #DIV/0! | D44: =H6&" "&SUBSTITUTE(SUBSTITUTE(SUBSTITUTE(J6&K6,"000nM","uM"),"000uM","mM"),"000ug","mg")&" "&ROUND(1/(E45/E44+1),5)&"x" -> #DIV/0! | E44: =$I$32*I6/J6*$E$33 -> #DIV/0! | F44: =N6&" "&SUBSTITUTE(SUBSTITUTE(SUBSTITUTE(P6&Q6,"000nM","uM"),"000uM","mM"),"000ug","mg")&" "&ROUND(1/(G45/G44+1),5)&"x" -> #DIV/0! | G44: =$K$32*O6/P6*$G$33 -> #DIV/0! | J44: =Tally!C10 | M44: =SUMIF($B$36:$F$86,J44,$C$36:$G$85) -> 0 | N44: =SUMIF($B$36:$F$85,J44,$C$37:$G$85) -> #DIV/0! | P44: =M44/N44*Q44 -> #DIV/0! | Q44: =ROUND(MAX(1.1*N44,0.5*N44/M44)/500+0.5,0)*500 -> #DIV/0!
B45: medium | C45: =$C$33-C44 -> #DIV/0! | D45: medium | E45: =$E$33-SUM($E$87:$E$88)-E44 -> #DIV/0! | F45: medium | G45: =$G$33-SUM($G$87:$G$88)-G44 -> #DIV/0! | J45: =Tally!C11 | M45: =SUMIF($B$36:$F$86,J45,$C$36:$G$85) -> 0 | N45: =SUMIF($B$36:$F$85,J45,$C$37:$G$85) -> #DIV/0! | P45: =M45/N45*Q45 -> #DIV/0! | Q45: =ROUND(MAX(1.1*N45,0.5*N45/M45)/500+0.5,0)*500 -> #DIV/0!
A46: =A7 -> F1 | B46: =B7&" "&SUBSTITUTE(SUBSTITUTE(SUBSTITUTE(D7&E7,"000nM","uM"),"000uM","mM"),"000ug","mg")&" "&ROUND(1/(C47/C46+1),5)&"x" -> #DIV/0! | C46: =$I$32*C7/D7*$C$33 -> #DIV/0! | D46: =H7&" "&SUBSTITUTE(SUBSTITUTE(SUBSTITUTE(J7&K7,"000nM","uM"),"000uM","mM"),"000ug","mg")&" "&ROUND(1/(E47/E46+1),5)&"x" -> #DIV/0! | E46: =$I$32*I7/J7*$E$33 -> #DIV/0! | F46: =N7&" "&SUBSTITUTE(SUBSTITUTE(SUBSTITUTE(P7&Q7,"000nM","uM"),"000uM","mM"),"000ug","mg")&" "&ROUND(1/(G47/G46+1),5)&"x" -> #DIV/0! | G46: =$K$32*O7/P7*$G$33 -> #DIV/0! | J46: =Tally!C12 | M46: =SUMIF($B$36:$F$86,J46,$C$36:$G$85) -> 0 | N46: =SUMIF($B$36:$F$85,J46,$C$37:$G$85) -> #DIV/0! | P46: =M46/N46*Q46 -> #DIV/0! | Q46: =ROUND(MAX(1.1*N46,0.5*N46/M46)/500+0.5,0)*500 -> #DIV/0!
B47: medium | C47: =$C$33-C46 -> #DIV/0! | D47: medium | E47: =$E$33-SUM($E$87:$E$88)-E46 -> #DIV/0! | F47: medium | G47: =$G$33-SUM($G$87:$G$88)-G46 -> #DIV/0! | J47: =Tally!C13 | M47: =SUMIF($B$36:$F$86,J47,$C$36:$G$85) -> 0 | N47: =SUMIF($B$36:$F$85,J47,$C$37:$G$85) -> #DIV/0! | P47: =M47/N47*Q47 -> #DIV/0! | Q47: =ROUND(MAX(1.1*N47,0.5*N47/M47)/500+0.5,0)*500 -> #DIV/0!
B48: . | D48: . | F48: . | J48: =Tally!C14 | M48: =SUMIF($B$36:$F$86,J48,$C$36:$G$85) -> 0 | N48: =SUMIF($B$36:$F$85,J48,$C$37:$G$85) -> #DIV/0! | P48: =M48/N48*Q48 -> #DIV/0! | Q48: =ROUND(MAX(1.1*N48,0.5*N48/M48)/500+0.5,0)*500 -> #DIV/0!
A49: =A8 -> A2 | B49: =B8&" "&SUBSTITUTE(SUBSTITUTE(SUBSTITUTE(D8&E8,"000nM","uM"),"000uM","mM"),"000ug","mg")&" "&ROUND(1/(C50/C49+1),5)&"x" -> #DIV/0! | C49: =$I$32*C8/D8*$C$33 -> #DIV/0! | D49: =H8&" "&SUBSTITUTE(SUBSTITUTE(SUBSTITUTE(J8&K8,"000nM","uM"),"000uM","mM"),"000ug","mg")&" "&ROUND(1/(E50/E49+1),5)&"x" -> #DIV/0! | E49: =$I$32*I8/J8*$E$33 -> #DIV/0! | F49: =N8&" "&SUBSTITUTE(SUBSTITUTE(SUBSTITUTE(P8&Q8,"000nM","uM"),"000uM","mM"),"000ug","mg")&" "&ROUND(1/(G50/G49+1),5)&"x" -> #DIV/0! | G49: =$K$32*O8/P8*$G$33 -> #DIV/0! | J49: =Tally!C15 | M49: =SUMIF($B$36:$F$86,J49,$C$36:$G$85) -> 0 | N49: =SUMIF($B$36:$F$85,J49,$C$37:$G$85) -> #DIV/0! | P49: =M49/N49*Q49 -> #DIV/0! | Q49: =ROUND(MAX(1.1*N49,0.5*N49/M49)/500+0.5,0)*500 -> #DIV/0!
B50: medium | C50: =$C$33-C49 -> #DIV/0! | D50: medium | E50: =$E$33-SUM($E$87:$E$88)-E49 -> #DIV/0! | F50: medium | G50: =$G$33-SUM($G$87:$G$88)-G49 -> #DIV/0! | J50: =Tally!C16 | M50: =SUMIF($B$36:$F$86,J50,$C$36:$G$85) -> 0 | N50: =SUMIF($B$36:$F$85,J50,$C$37:$G$85) -> #DIV/0! | P50: =M50/N50*Q50 -> #DIV/0! | Q50: =ROUND(MAX(1.1*N50,0.5*N50/M50)/500+0.5,0)*500 -> #DIV/0!
A51: =A9 -> B2 | B51: =B9&" "&SUBSTITUTE(SUBSTITUTE(SUBSTITUTE(D9&E9,"000nM","uM"),"000uM","mM"),"000ug","mg")&" "&ROUND(1/(C52/C51+1),5)&"x" -> #DIV/0! | C51: =$I$32*C9/D9*$C$33 -> #DIV/0! | D51: =H9&" "&SUBSTITUTE(SUBSTITUTE(SUBSTITUTE(J9&K9,"000nM","uM"),"000uM","mM"),"000ug","mg")&" "&ROUND(1/(E52/E51+1),5)&"x" -> #DIV/0! | E51: =$I$32*I9/J9*$E$33 -> #DIV/0! | F51: =N9&" "&SUBSTITUTE(SUBSTITUTE(SUBSTITUTE(P9&Q9,"000nM","uM"),"000uM","mM"),"000ug","mg")&" "&ROUND(1/(G52/G51+1),5)&"x" -> #DIV/0! | G51: =$K$32*O9/P9*$G$33 -> #DIV/0! | J51: =Tally!C17 | M51: =SUMIF($B$36:$F$86,J51,$C$36:$G$85) -> 0 | N51: =SUMIF($B$36:$F$85,J51,$C$37:$G$85) -> #DIV/0! | P51: =M51/N51*Q51 -> #DIV/0! | Q51: =ROUND(MAX(1.1*N51,0.5*N51/M51)/500+0.5,0)*500 -> #DIV/0!
...

Sheet Tally
A1: =Plate!B36 -> Glucose 500mM 0.052x
A2: =Plate!B38 -> Glucose+FCCP 120uM 0.00167x | C2: {=IFERROR(INDEX(A$1:A$72,MATCH(SUM(COUNTIF(C$1:C1,A$1:A$72)),COUNTIF(A$1:A$72,"<"&A$1:A$72),0)),"")} -> Glucose 500mM 0.052x
A3: =Plate!B40 -> #DIV/0! | C3: {=IFERROR(INDEX(A$1:A$72,MATCH(SUM(COUNTIF(C$1:C2,A$1:A$72)),COUNTIF(A$1:A$72,"<"&A$1:A$72),0)),"")} -> Glucose+FCCP 120uM 0.00167x
A4: =Plate!B42 -> #DIV/0! | C4: {=IFERROR(INDEX(A$1:A$72,MATCH(SUM(COUNTIF(C$1:C3,A$1:A$72)),COUNTIF(A$1:A$72,"<"&A$1:A$72),0)),"")} -> Oligom 8mg/ml 0.001x
A5: =Plate!B44 -> #DIV/0! | C5: {=IFERROR(INDEX(A$1:A$72,MATCH(SUM(COUNTIF(C$1:C4,A$1:A$72)),COUNTIF(A$1:A$72,"<"&A$1:A$72),0)),"")}
A6: =Plate!B46 -> #DIV/0! | C6: {=IFERROR(INDEX(A$1:A$72,MATCH(SUM(COUNTIF(C$1:C5,A$1:A$72)),COUNTIF(A$1:A$72,"<"&A$1:A$72),0)),"")}
A7: =Plate!B49 -> #DIV/0! | C7: {=IFERROR(INDEX(A$1:A$72,MATCH(SUM(COUNTIF(C$1:C6,A$1:A$72)),COUNTIF(A$1:A$72,"<"&A$1:A$72),0)),"")}
A8: =Plate!B51 -> #DIV/0! | C8: {=IFERROR(INDEX(A$1:A$72,MATCH(SUM(COUNTIF(C$1:C7,A$1:A$72)),COUNTIF(A$1:A$72,"<"&A$1:A$72),0)),"")}
A9: =Plate!B53 -> #DIV/0! | C9: {=IFERROR(INDEX(A$1:A$72,MATCH(SUM(COUNTIF(C$1:C8,A$1:A$72)),COUNTIF(A$1:A$72,"<"&A$1:A$72),0)),"")}
A10: =Plate!B55 -> #DIV/0! | C10: {=IFERROR(INDEX(A$1:A$72,MATCH(SUM(COUNTIF(C$1:C9,A$1:A$72)),COUNTIF(A$1:A$72,"<"&A$1:A$72),0)),"")}
A11: =Plate!B57 -> #DIV/0! | C11: {=IFERROR(INDEX(A$1:A$72,MATCH(SUM(COUNTIF(C$1:C10,A$1:A$72)),COUNTIF(A$1:A$72,"<"&A$1:A$72),0)),"")}
A12: =Plate!B59 -> #DIV/0! | C12: {=IFERROR(INDEX(A$1:A$72,MATCH(SUM(COUNTIF(C$1:C11,A$1:A$72)),COUNTIF(A$1:A$72,"<"&A$1:A$72),0)),"")}
A13: =Plate!B62 -> #DIV/0! | C13: {=IFERROR(INDEX(A$1:A$72,MATCH(SUM(COUNTIF(C$1:C12,A$1:A$72)),COUNTIF(A$1:A$72,"<"&A$1:A$72),0)),"")}
A14: =Plate!B64 -> #DIV/0! | C14: {=IFERROR(INDEX(A$1:A$72,MATCH(SUM(COUNTIF(C$1:C13,A$1:A$72)),COUNTIF(A$1:A$72,"<"&A$1:A$72),0)),"")}
A15: =Plate!B66 -> #DIV/0! | C15: {=IFERROR(INDEX(A$1:A$72,MATCH(SUM(COUNTIF(C$1:C14,A$1:A$72)),COUNTIF(A$1:A$72,"<"&A$1:A$72),0)),"")}
A16: =Plate!B68 -> #DIV/0! | C16: {=IFERROR(INDEX(A$1:A$72,MATCH(SUM(COUNTIF(C$1:C15,A$1:A$72)),COUNTIF(A$1:A$72,"<"&A$1:A$72),0)),"")}
A17: =Plate!B70 -> #DIV/0! | C17: {=IFERROR(INDEX(A$1:A$72,MATCH(SUM(COUNTIF(C$1:C16,A$1:A$72)),COUNTIF(A$1:A$72,"<"&A$1:A$72),0)),"")}
A18: =Plate!B72 -> #DIV/0! | C18: {=IFERROR(INDEX(A$1:A$72,MATCH(SUM(COUNTIF(C$1:C17,A$1:A$72)),COUNTIF(A$1:A$72,"<"&A$1:A$72),0)),"")}
A19: =Plate!D36 -> Oligom 8mg/ml 0.001x | C19: {=IFERROR(INDEX(A$1:A$72,MATCH(SUM(COUNTIF(C$1:C18,A$1:A$72)),COUNTIF(A$1:A$72,"<"&A$1:A$72),0)),"")}
A20: =Plate!D38 -> Oligom 8mg/ml 0.001x | C20: {=IFERROR(INDEX(A$1:A$72,MATCH(SUM(COUNTIF(C$1:C19,A$1:A$72)),COUNTIF(A$1:A$72,"<"&A$1:A$72),0)),"")}
A21: =Plate!D40 -> #DIV/0! | C21: {=IFERROR(INDEX(A$1:A$72,MATCH(SUM(COUNTIF(C$1:C20,A$1:A$72)),COUNTIF(A$1:A$72,"<"&A$1:A$72),0)),"")}
A22: =Plate!D42 -> #DIV/0! | C22: {=IFERROR(INDEX(A$1:A$72,MATCH(SUM(COUNTIF(C$1:C21,A$1:A$72)),COUNTIF(A$1:A$72,"<"&A$1:A$72),0)),"")}
A23: =Plate!D44 -> #DIV/0! | C23: {=IFERROR(INDEX(A$1:A$72,MATCH(SUM(COUNTIF(C$1:C22,A$1:A$72)),COUNTIF(A$1:A$72,"<"&A$1:A$72),0)),"")}
A24: =Plate!D46 -> #DIV/0! | C24: {=IFERROR(INDEX(A$1:A$72,MATCH(SUM(COUNTIF(C$1:C23,A$1:A$72)),COUNTIF(A$1:A$72,"<"&A$1:A$72),0)),"")}
A25: =Plate!D49 -> #DIV/0! | C25: {=IFERROR(INDEX(A$1:A$72,MATCH(SUM(COUNTIF(C$1:C24,A$1:A$72)),COUNTIF(A$1:A$72,"<"&A$1:A$72),0)),"")}
A26: =Plate!D51 -> #DIV/0! | C26: {=IFERROR(INDEX(A$1:A$72,MATCH(SUM(COUNTIF(C$1:C25,A$1:A$72)),COUNTIF(A$1:A$72,"<"&A$1:A$72),0)),"")}
A27: =Plate!D53 -> #DIV/0! | C27: {=IFERROR(INDEX(A$1:A$72,MATCH(SUM(COUNTIF(C$1:C26,A$1:A$72)),COUNTIF(A$1:A$72,"<"&A$1:A$72),0)),"")}
A28: =Plate!D55 -> #DIV/0! | C28: {=IFERROR(INDEX(A$1:A$72,MATCH(SUM(COUNTIF(C$1:C27,A$1:A$72)),COUNTIF(A$1:A$72,"<"&A$1:A$72),0)),"")}
A29: =Plate!D57 -> #DIV/0! | C29: {=IFERROR(INDEX(A$1:A$72,MATCH(SUM(COUNTIF(C$1:C28,A$1:A$72)),COUNTIF(A$1:A$72,"<"&A$1:A$72),0)),"")}
A30: =Plate!D59 -> #DIV/0! | C30: {=IFERROR(INDEX(A$1:A$72,MATCH(SUM(COUNTIF(C$1:C29,A$1:A$72)),COUNTIF(A$1:A$72,"<"&A$1:A$72),0)),"")}
A31: =Plate!D62 -> #DIV/0! | C31: {=IFERROR(INDEX(A$1:A$72,MATCH(SUM(COUNTIF(C$1:C30,A$1:A$72)),COUNTIF(A$1:A$72,"<"&A$1:A$72),0)),"")}
A32: =Plate!D64 -> #DIV/0! | C32: {=IFERROR(INDEX(A$1:A$72,MATCH(SUM(COUNTIF(C$1:C31,A$1:A$72)),COUNTIF(A$1:A$72,"<"&A$1:A$72),0)),"")}
A33: =Plate!D66 -> #DIV/0! | C33: {=IFERROR(INDEX(A$1:A$72,MATCH(SUM(COUNTIF(C$1:C32,A$1:A$72)),COUNTIF(A$1:A$72,"<"&A$1:A$72),0)),"")}
A34: =Plate!D68 -> #DIV/0! | C34: {=IFERROR(INDEX(A$1:A$72,MATCH(SUM(COUNTIF(C$1:C33,A$1:A$72)),COUNTIF(A$1:A$72,"<"&A$1:A$72),0)),"")}
A35: =Plate!D70 -> #DIV/0! | C35: {=IFERROR(INDEX(A$1:A$72,MATCH(SUM(COUNTIF(C$1:C34,A$1:A$72)),COUNTIF(A$1:A$72,"<"&A$1:A$72),0)),"")}
A36: =Plate!D72 -> #DIV/0! | C36: {=IFERROR(INDEX(A$1:A$72,MATCH(SUM(COUNTIF(C$1:C35,A$1:A$72)),COUNTIF(A$1:A$72,"<"&A$1:A$72),0)),"")}
A37: =Plate!F36 -> #DIV/0! | C37: {=IFERROR(INDEX(A$1:A$72,MATCH(SUM(COUNTIF(C$1:C36,A$1:A$72)),COUNTIF(A$1:A$72,"<"&A$1:A$72),0)),"")}
A38: =Plate!F38 -> #DIV/0! | C38: {=IFERROR(INDEX(A$1:A$72,MATCH(SUM(COUNTIF(C$1:C37,A$1:A$72)),COUNTIF(A$1:A$72,"<"&A$1:A$72),0)),"")}
A39: =Plate!F40 -> #DIV/0! | C39: {=IFERROR(INDEX(A$1:A$72,MATCH(SUM(COUNTIF(C$1:C38,A$1:A$72)),COUNTIF(A$1:A$72,"<"&A$1:A$72),0)),"")}
A40: =Plate!F42 -> #DIV/0! | C40: {=IFERROR(INDEX(A$1:A$72,MATCH(SUM(COUNTIF(C$1:C39,A$1:A$72)),COUNTIF(A$1:A$72,"<"&A$1:A$72),0)),"")}
...

Sheet Checklist
A1: =Plate!A36 -> A1 | B1: =Plate!B36 -> Glucose 500mM 0.052x | C1: =Plate!D36 -> Oligom 8mg/ml 0.001x
A2: =Plate!A38 -> B1 | B2: =Plate!B38 -> Glucose+FCCP 120uM 0.00167x | C2: =Plate!D38 -> Oligom 8mg/ml 0.001x
A3: =Plate!A40 -> C1 | B3: =Plate!B40 -> #DIV/0! | C3: =Plate!D40 -> #DIV/0!
A4: =Plate!A42 -> D1 | B4: =Plate!B42 -> #DIV/0! | C4: =Plate!D42 -> #DIV/0!
A5: =Plate!A44 -> E1 | B5: =Plate!B44 -> #DIV/0! | C5: =Plate!D44 -> #DIV/0!
A6: =Plate!A46 -> F1 | B6: =Plate!B46 -> #DIV/0! | C6: =Plate!D46 -> #DIV/0!
E7: Reservoir Plate Layout
A8: =Plate!A49 -> A2 | B8: =Plate!B49 -> #DIV/0! | C8: =Plate!D49 -> #DIV/0! | E8: Copy and paste this layout to Onenote and add checkboxes
A9: =Plate!A51 -> B2 | B9: =Plate!B51 -> #DIV/0! | C9: =Plate!D51 -> #DIV/0! | F9: 1 (first addition) | G9: 2 | H9: 3 | I9: 4 | J9: 5 | K9: 6 (second addition) | L9: 7 | M9: 8 | N9: 9
A10: =Plate!A53 -> C2 | B10: =Plate!B53 -> #DIV/0! | C10: =Plate!D53 -> #DIV/0! | E10: A | F10: =B1 -> Glucose 500mM 0.052x | G10: =B8 -> #DIV/0! | H10: =B15 -> #DIV/0! | I10: =B22 -> #DIV/0! | K10: =C1 -> Oligom 8mg/ml 0.001x | L10: =C8 -> #DIV/0! | M10: =C15 -> #DIV/0! | N10: =C22 -> #DIV/0!
A11: =Plate!A55 -> D2 | B11: =Plate!B55 -> #DIV/0! | C11: =Plate!D55 -> #DIV/0! | E11: B | F11: =B2 -> Glucose+FCCP 120uM 0.00167x | G11: =B9 -> #DIV/0! | H11: =B16 -> #DIV/0! | I11: =B23 -> #DIV/0! | K11: =C2 -> Oligom 8mg/ml 0.001x | L11: =C9 -> #DIV/0! | M11: =C16 -> #DIV/0! | N11: =C23 -> #DIV/0!
A12: =Plate!A57 -> E2 | B12: =Plate!B57 -> #DIV/0! | C12: =Plate!D57 -> #DIV/0! | E12: C | F12: =B3 -> #DIV/0! | G12: =B10 -> #DIV/0! | H12: =B17 -> #DIV/0! | I12: =B24 -> #DIV/0! | K12: =C3 -> #DIV/0! | L12: =C10 -> #DIV/0! | M12: =C17 -> #DIV/0! | N12: =C24 -> #DIV/0!
A13: =Plate!A59 -> F2 | B13: =Plate!B59 -> #DIV/0! | C13: =Plate!D59 -> #DIV/0! | E13: D | F13: =B4 -> #DIV/0! | G13: =B11 -> #DIV/0! | H13: =B18 -> #DIV/0! | I13: =B25 -> #DIV/0! | K13: =C4 -> #DIV/0! | L13: =C11 -> #DIV/0! | M13: =C18 -> #DIV/0! | N13: =C25 -> #DIV/0!
E14: E | F14: =B5 -> #DIV/0! | G14: =B12 -> #DIV/0! | H14: =B19 -> #DIV/0! | I14: =B26 -> #DIV/0! | K14: =C5 -> #DIV/0! | L14: =C12 -> #DIV/0! | M14: =C19 -> #DIV/0! | N14: =C26 -> #DIV/0!
A15: =Plate!A62 -> A3 | B15: =Plate!B62 -> #DIV/0! | C15: =Plate!D62 -> #DIV/0! | E15: F | F15: =B6 -> #DIV/0! | G15: =B13 -> #DIV/0! | H15: =B20 -> #DIV/0! | I15: =B27 -> #DIV/0! | K15: =C6 -> #DIV/0! | L15: =C13 -> #DIV/0! | M15: =C20 -> #DIV/0! | N15: =C27 -> #DIV/0!
A16: =Plate!A64 -> B3 | B16: =Plate!B64 -> #DIV/0! | C16: =Plate!D64 -> #DIV/0! | E16: # | F16: Transfer 2x175ul from #1->#2 Add 280ul for -90/+90 addition
A17: =Plate!A66 -> C3 | B17: =Plate!B66 -> #DIV/0! | C17: =Plate!D66 -> #DIV/0!
A18: =Plate!A68 -> D3 | B18: =Plate!B68 -> #DIV/0! | C18: =Plate!D68 -> #DIV/0!
A19: =Plate!A70 -> E3 | B19: =Plate!B70 -> #DIV/0! | C19: =Plate!D70 -> #DIV/0!
A20: =Plate!A72 -> F3 | B20: =Plate!B72 -> #DIV/0! | C20: =Plate!D72 -> #DIV/0!
A22: =Plate!A75 -> A4 | B22: =Plate!B75 -> #DIV/0! | C22: =Plate!D75 -> #DIV/0!
A23: =Plate!A77 -> B4 | B23: =Plate!B77 -> #DIV/0! | C23: =Plate!D77 -> #DIV/0!
A24: =Plate!A79 -> C4 | B24: =Plate!B79 -> #DIV/0! | C24: =Plate!D79 -> #DIV/0!
A25: =Plate!A81 -> D4 | B25: =Plate!B81 -> #DIV/0! | C25: =Plate!D81 -> #DIV/0!
A26: =Plate!A83 -> E4 | B26: =Plate!B83 -> #DIV/0! | C26: =Plate!D83 -> #DIV/0!
A27: =Plate!A85 -> F4 | B27: =Plate!B85 -> #DIV/0! | C27: =Plate!D85 -> #DIV/0!

Sheet Condition Names
A1: =Plate!A2 -> A1 | B1: ="("&Plate!L2&")"&Plate!B2&Plate!C2&";"&Plate!H2&Plate!I2&";"&Plate!N2&Plate!O2 -> ()Glucose13;Oligom2;
A2: =Plate!A3 -> B1 | B2: ="("&Plate!L3&")"&Plate!B3&Plate!C3&";"&Plate!H3&Plate!I3&";"&Plate!N3&Plate!O3 -> ()Glucose+FCCP100;Oligom2;
A3: =Plate!A4 -> C1 | B3: ="("&Plate!L4&")"&Plate!B4&Plate!C4&";"&Plate!H4&Plate!I4&";"&Plate!N4&Plate!O4 -> ();;
A4: =Plate!A5 -> D1 | B4: ="("&Plate!L5&")"&Plate!B5&Plate!C5&";"&Plate!H5&Plate!I5&";"&Plate!N5&Plate!O5 -> ();;
A5: =Plate!A6 -> E1 | B5: ="("&Plate!L6&")"&Plate!B6&Plate!C6&";"&Plate!H6&Plate!I6&";"&Plate!N6&Plate!O6 -> ();;
A6: =Plate!A7 -> F1 | B6: ="("&Plate!L7&")"&Plate!B7&Plate!C7&";"&Plate!H7&Plate!I7&";"&Plate!N7&Plate!O7 -> ();;
A7: =Plate!A8 -> A2 | B7: ="("&Plate!L8&")"&Plate!B8&Plate!C8&";"&Plate!H8&Plate!I8&";"&Plate!N8&Plate!O8 -> ();;
A8: =Plate!A9 -> B2 | B8: ="("&Plate!L9&")"&Plate!B9&Plate!C9&";"&Plate!H9&Plate!I9&";"&Plate!N9&Plate!O9 -> ();;
A9: =Plate!A10 -> C2 | B9: ="("&Plate!L10&")"&Plate!B10&Plate!C10&";"&Plate!H10&Plate!I10&";"&Plate!N10&Plate!O10 -> ();;
A10: =Plate!A11 -> D2 | B10: ="("&Plate!L11&")"&Plate!B11&Plate!C11&";"&Plate!H11&Plate!I11&";"&Plate!N11&Plate!O11 -> ();;
A11: =Plate!A12 -> E2 | B11: ="("&Plate!L12&")"&Plate!B12&Plate!C12&";"&Plate!H12&Plate!I12&";"&Plate!N12&Plate!O12 -> ();;
A12: =Plate!A13 -> F2 | B12: ="("&Plate!L13&")"&Plate!B13&Plate!C13&";"&Plate!H13&Plate!I13&";"&Plate!N13&Plate!O13 -> ();;
... A24: =Plate!A25 -> F4 | B24: ="("&Plate!L25&")"&Plate!B25&Plate!C25&";"&Plate!H25&Plate!I25&";"&Plate!N25&Plate!O25 -> ();;
A26: Image Analyst List (paste position list below to column A)
A27: A1_1 | B27: =OFFSET($A$1,MATCH(LEFT(A27,2),$A$1:$A$24,0)-1,1) -> ()Glucose13;Oligom2;
A28: A1_2 | B28: =OFFSET($A$1,MATCH(LEFT(A28,2),$A$1:$A$24,0)-1,1) -> ()Glucose13;Oligom2;
A29: A2_2 | B29: =OFFSET($A$1,MATCH(LEFT(A29,2),$A$1:$A$24,0)-1,1) -> ();;
A30: A2_1 | B30: =OFFSET($A$1,MATCH(LEFT(A30,2),$A$1:$A$24,0)-1,1) -> ();;
A31: B2_2 | B31: =OFFSET($A$1,MATCH(LEFT(A31,2),$A$1:$A$24,0)-1,1) -> ();;
A32: B2_1 | B32: =OFFSET($A$1,MATCH(LEFT(A32,2),$A$1:$A$24,0)-1,1) -> ();;
A33: C2_2 | B33: =OFFSET($A$1,MATCH(LEFT(A33,2),$A$1:$A$24,0)-1,1) -> ();;
A34: C2_1 | B34: =OFFSET($A$1,MATCH(LEFT(A34,2),$A$1:$A$24,0)-1,1) -> ();;
A35: D2_1 | B35: =OFFSET($A$1,MATCH(LEFT(A35,2),$A$1:$A$24,0)-1,1) -> ();;
A36: D2_2 | B36: =OFFSET($A$1,MATCH(LEFT(A36,2),$A$1:$A$24,0)-1,1) -> ();;
A37: E2_1 | B37: =OFFSET($A$1,MATCH(LEFT(A37,2),$A$1:$A$24,0)-1,1) -> ();;
A38: E2_2 | B38: =OFFSET($A$1,MATCH(LEFT(A38,2),$A$1:$A$24,0)-1,1) -> ();;
... A74: B1_2 | B74: =OFFSET($A$1,MATCH(LEFT(A74,2),$A$1:$A$24,0)-1,1) -> ()Glucose+FCCP100;Oligom2;

Sheet Randomize
M1: =RAND() -> 0.13561219 | N1: 1 | O1: =B1&";"&H1 -> ; | R1: Resort by L, (B-N)
M2: =RAND() -> 0.067280942 | N2: 2 | O2: =B2&";"&H2 -> ; | R2: Sort first each genotype for M (sorting only B-M).
M3: =RAND() -> 0.32451661 | N3: 3 | O3: =B3&";"&H3 -> ; | R3: Then sort everything by N
M4: =RAND() -> 0.17673383 | N4: 4 | O4: =B4&";"&H4 -> ;
M5: =RAND() -> 0.47758879 | N5: 5 | O5: =B5&";"&H5 -> ;
M6: =RAND() -> 0.78506307 | N6: 6 | O6: =B6&";"&H6 -> ;
M7: =RAND() -> 0.37144235 | N7: 7 | O7: =B7&";"&H7 -> ;
M8: =RAND() -> 0.44852686 | N8: 8 | O8: =B8&";"&H8 -> ;
M9: =RAND() -> 0.34014973 | N9: 9 | O9: =B9&";"&H9 -> ;
M10: =RAND() -> 0.68686089 | N10: 10 | O10: =B10&";"&H10 -> ;
M11: =RAND() -> 0.98106768 | N11: 11 | O11: =B11&";"&H11 -> ;
M12: =RAND() -> 0.44689387 | N12: 12 | O12: =B12&";"&H12 -> ;
M13: =RAND() -> 0.058004325 | N13: 13 | O13: =B13&";"&H13 -> ;
M14: =RAND() -> 0.70427191 | N14: 14 | O14: =B14&";"&H14 -> ;
M15: =RAND() -> 0.87099968 | N15: 15 | O15: =B15&";"&H15 -> ;
... M18: =RAND() -> 0.61752768 | N18: 18 | O18: =B18&";"&H18 -> ;
